<?xml version="1.0" ?>
<robot xmlns:xacro="http://www.ros.org/wiki/xacro">

  <material name="green">
    <color rgba="0.0 0.8 0.0 1.0"/>
  </material>
  <material name="red">
    <color rgba="0.949 0.321 0.274 1.0"/>
  </material>
  <material name="grey">
    <color rgba="0.7 0.7 0.7 1.0"/>
  </material>
  <material name="dark_grey">
    <color rgba="0.35 0.35 0.39 1.0"/>
  </material>
  <material name="yellow">
    <color rgba="1.0 0.78 0 1.0"/>
  </material>

  <link name="tripod">
     <visual>
      <origin rpy="1.57 0 0" xyz="0 0 0"/>
      <geometry>
        <mesh filename="package://scanner_description/meshes/tripod.stl" scale="0.001 0.001 0.001"/>
      </geometry>
      <material name="dark_grey"/>
    </visual>
  </link>

  <link name="base_link">
     <visual name="base_link_visual">
      <origin rpy="0 0 0" xyz="-0.021 -0.021 0"/>
      <geometry>
        <mesh filename="package://scanner_description/meshes/nema17.stl" scale="0.001 0.001 0.001"/>
      </geometry>
      <material name="red"/>
    </visual>
  </link>

   <joint name="tripod_joint" type="fixed">
    <parent link="tripod"/>
    <child link="base_link"/>
    <origin rpy="0 0 0" xyz="0 0.0 1.3"/>
  </joint>

  <link name="head"/> 

  <joint name="head_joint" type="revolute">
    <parent link="base_link"/>
    <child link="head"/>
    <origin rpy="0 0 0" xyz="0 0 0.05"/>
    <axis xyz="0 0 1"/>
    <limit effort="10.0" lower="0" upper="3.14" velocity="0.5"/>
  </joint>

  <link name="neato_laser">
    <visual>
      <origin rpy="0 0 -1.57" xyz="0 0 0"/>
      <geometry>
        <mesh filename="package://scanner_description/meshes/lidar.stl" scale="0.001 0.001 0.001"/>
      </geometry>
      <material name="yellow"/>
    </visual>
  </link>

  <joint name="neato_laser_joint" type="fixed">
    <parent link="head"/>
    <child link="neato_laser"/>
    <origin rpy="0 -1.57 0" xyz="0 0.0 0.06"/>
  </joint>
  
  <link name="pointcloud"/>

   <joint name="pointcloud_joint" type="fixed">
    <parent link="base_link"/>
    <child link="pointcloud"/>
    <origin rpy="0 0 0" xyz="0 0.0 0.11"/>
  </joint>

</robot>
